<sdf version='1.6'>
  <world name='default'>
    <light name='sun' type='directional'>
      <cast_shadows>1</cast_shadows>
      <pose frame=''>0 0 10 0 -0 0</pose>
      <diffuse>0.8 0.8 0.8 1</diffuse>
      <specular>0.1 0.1 0.1 1</specular>
      <attenuation>
        <range>1000</range>
        <constant>0.9</constant>
        <linear>0.01</linear>
        <quadratic>0.001</quadratic>
      </attenuation>
      <direction>-0.5 0.5 -1</direction>
    </light>
    <model name='ground_plane'>
      <static>1</static>
      <link name='link'>
        <collision name='collision'>
          <geometry>
            <plane>
              <normal>0 0 1</normal>
              <size>100 100</size>
            </plane>
          </geometry>
          <surface>
            <friction>
              <ode>
                <mu>100</mu>
                <mu2>50</mu2>
              </ode>
              <torsional>
                <ode/>
              </torsional>
            </friction>
            <contact>
              <ode/>
            </contact>
            <bounce/>
          </surface>
          <max_contacts>10</max_contacts>
        </collision>
        <visual name='visual'>
          <cast_shadows>0</cast_shadows>
          <geometry>
            <plane>
              <normal>0 0 1</normal>
              <size>100 100</size>
            </plane>
          </geometry>
          <material>
            <script>
              <uri>file://media/materials/scripts/gazebo.material</uri>
              <name>Gazebo/Grey</name>
            </script>
          </material>
        </visual>
        <self_collide>0</self_collide>
        <kinematic>0</kinematic>
        <gravity>1</gravity>
      </link>
    </model>
    <gravity>0 0 -9.8</gravity>
    <magnetic_field>6e-06 2.3e-05 -4.2e-05</magnetic_field>
    <atmosphere type='adiabatic'/>
    <physics name='default_physics' default='0' type='ode'>
      <max_step_size>0.001</max_step_size>
      <real_time_factor>1</real_time_factor>
      <real_time_update_rate>1000</real_time_update_rate>
    </physics>
    <scene>
      <ambient>0.4 0.4 0.4 1</ambient>
      <background>0.7 0.7 0.7 1</background>
      <shadows>1</shadows>
    </scene>
    <spherical_coordinates>
      <surface_model>EARTH_WGS84</surface_model>
      <latitude_deg>0</latitude_deg>
      <longitude_deg>0</longitude_deg>
      <elevation>0</elevation>
      <heading_deg>0</heading_deg>
    </spherical_coordinates>

    <model name='scara'>
      <link name='base_link'>
        <pose frame=''>0 0 0 0 -0 0</pose>
        <inertial>
          <pose frame=''>0 0 0 0 -0 0</pose>
          <mass>1000</mass>
          <inertia>
            <ixx>0</ixx>
            <ixy>0</ixy>
            <ixz>0</ixz>
            <iyy>0</iyy>
            <iyz>0</iyz>
            <izz>1</izz>
          </inertia>
        </inertial>
        <collision name='base_link_collision'>
          <pose frame=''>0 0 0 0 -0 0</pose>
          <geometry>
            <cylinder>
              <length>1.2</length>
              <radius>0.15</radius>
            </cylinder>
          </geometry>
          <max_contacts>10</max_contacts>
          <surface>
            <contact>
              <ode/>
            </contact>
            <bounce/>
            <friction>
              <torsional>
                <ode/>
              </torsional>
              <ode/>
            </friction>
          </surface>
        </collision>
        <visual name='base_link_visual'>
          <pose frame=''>0 0 0.6 0 -0 0</pose>
          <geometry>
            <cylinder>
              <length>1.2</length>
              <radius>0.15</radius>
            </cylinder>
          </geometry>
        </visual>
        <self_collide>0</self_collide>
        <kinematic>0</kinematic>
        <gravity>1</gravity>
      </link>

      <link name='first_link'>
        <pose frame=''>0 0 0.75 0 -0 0</pose>
        <inertial>
          <pose frame=''>0 0 0 0 -0 0</pose>
          <mass>10</mass>
          <inertia>
            <ixx>0</ixx>
            <ixy>0</ixy>
            <ixz>0</ixz>
            <iyy>0</iyy>
            <iyz>0</iyz>
            <izz>1</izz>
          </inertia>
        </inertial>
        <collision name='first_link_collision'>
          <pose frame=''>0 0 0 0 -0 0</pose>
          <geometry>
            <box>
              <size>0.9 0.15 0.3</size>
            </box>
          </geometry>
          <max_contacts>10</max_contacts>
          <surface>
            <contact>
              <ode/>
            </contact>
            <bounce/>
            <friction>
              <torsional>
                <ode/>
              </torsional>
              <ode/>
            </friction>
          </surface>
        </collision>
        <visual name='first_link_visual'>
          <pose frame=''>0.45 0 0 0 -0 0</pose>
          <geometry>
            <box>
              <size>0.9 0.15 0.3</size>
            </box>
          </geometry>
        </visual>
        <self_collide>0</self_collide>
        <kinematic>0</kinematic>
        <gravity>1</gravity>
      </link>
      <joint name='base_to_first_link' type='revolute'>
        <child>first_link</child>
        <parent>base_link</parent>
        <axis>
          <xyz>0 0 1</xyz>
          <limit>
            <lower>-2.6</lower>
            <upper>2.6</upper>
            <effort>1000</effort>
            <velocity>0.5</velocity>
          </limit>
          <dynamics>
            <spring_reference>0</spring_reference>
            <spring_stiffness>0</spring_stiffness>
          </dynamics>
          <use_parent_model_frame>1</use_parent_model_frame>
        </axis>
      </joint>
      <link name='first_joint'>
        <pose frame=''>0.9 0 0.75 0 -0 0</pose>
        <inertial>
          <pose frame=''>0 0 0 0 -0 0</pose>
          <mass>20</mass>
          <inertia>
            <ixx>0</ixx>
            <ixy>0</ixy>
            <ixz>0</ixz>
            <iyy>0</iyy>
            <iyz>0</iyz>
            <izz>2</izz>
          </inertia>
        </inertial>
        <collision name='first_joint_collision'>
          <pose frame=''>0 0 0 0 -0 0</pose>
          <geometry>
            <cylinder>
              <length>0.3</length>
              <radius>0.15</radius>
            </cylinder>
          </geometry>
          <max_contacts>10</max_contacts>
          <surface>
            <contact>
              <ode/>
            </contact>
            <bounce/>
            <friction>
              <torsional>
                <ode/>
              </torsional>
              <ode/>
            </friction>
          </surface>
        </collision>
        <collision name='first_joint_fixed_joint_lump__second_link_collision_1'>
          <pose frame=''>0 0 0 0 -0 0</pose>
          <geometry>
            <box>
              <size>0.9 0.15 0.3</size>
            </box>
          </geometry>
          <max_contacts>10</max_contacts>
          <surface>
            <contact>
              <ode/>
            </contact>
            <bounce/>
            <friction>
              <torsional>
                <ode/>
              </torsional>
              <ode/>
            </friction>
          </surface>
        </collision>
        <visual name='first_joint_visual'>
          <pose frame=''>0 0 0 0 -0 0</pose>
          <geometry>
            <cylinder>
              <length>0.3</length>
              <radius>0.15</radius>
            </cylinder>
          </geometry>
        </visual>
        <visual name='first_joint_fixed_joint_lump__second_link_visual_1'>
          <pose frame=''>0.45 0 0 0 -0 0</pose>
          <geometry>
            <box>
              <size>0.9 0.15 0.3</size>
            </box>
          </geometry>
        </visual>
        <self_collide>0</self_collide>
        <kinematic>0</kinematic>
        <gravity>1</gravity>
      </link>
      <joint name='first_link_to_first_joint' type='revolute'>
        <child>first_joint</child>
        <parent>first_link</parent>
        <axis>
          <xyz>0 0 1</xyz>
          <limit>
            <lower>-2.6</lower>
            <upper>2.6</upper>
            <effort>1000</effort>
            <velocity>0.5</velocity>
          </limit>
          <dynamics>
            <spring_reference>0</spring_reference>
            <spring_stiffness>0</spring_stiffness>
          </dynamics>
          <use_parent_model_frame>1</use_parent_model_frame>
        </axis>
      </joint>
      <link name='second_joint'>
        <pose frame=''>1.8 0 0.75 0 -0 0</pose>
        <inertial>
          <pose frame=''>0 0 0 0 -0 0</pose>
          <mass>10</mass>
          <inertia>
            <ixx>0</ixx>
            <ixy>0</ixy>
            <ixz>0</ixz>
            <iyy>0</iyy>
            <iyz>0</iyz>
            <izz>1</izz>
          </inertia>
        </inertial>
        <collision name='second_joint_collision'>
          <pose frame=''>0 0 0 0 -0 0</pose>
          <geometry>
            <cylinder>
              <length>0.3</length>
              <radius>0.15</radius>
            </cylinder>
          </geometry>
          <max_contacts>10</max_contacts>
          <surface>
            <contact>
              <ode/>
            </contact>
            <bounce/>
            <friction>
              <torsional>
                <ode/>
              </torsional>
              <ode/>
            </friction>
          </surface>
        </collision>
        <visual name='second_joint_visual'>
          <pose frame=''>0 0 0 0 -0 0</pose>
          <geometry>
            <cylinder>
              <length>0.3</length>
              <radius>0.15</radius>
            </cylinder>
          </geometry>
        </visual>
        <self_collide>0</self_collide>
        <kinematic>0</kinematic>
        <gravity>1</gravity>
      </link>
      <joint name='second_link_to_second_joint' type='revolute'>
        <child>second_joint</child>
        <parent>first_joint</parent>
        <axis>
          <xyz>0 0 1</xyz>
          <limit>
            <lower>-1e+16</lower>
            <upper>1e+16</upper>
          </limit>
          <dynamics>
            <spring_reference>0</spring_reference>
            <spring_stiffness>0</spring_stiffness>
          </dynamics>
          <use_parent_model_frame>1</use_parent_model_frame>
        </axis>
      </joint>
      <link name='third_link'>
        <pose frame=''>1.8 0 0.75 0 -0 0</pose>
        <inertial>
          <pose frame=''>0 0 -0.225 0 -0 0</pose>
          <mass>20</mass>
          <inertia>
            <ixx>1.0125</ixx>
            <ixy>0</ixy>
            <ixz>0</ixz>
            <iyy>1.0125</iyy>
            <iyz>0</iyz>
            <izz>2</izz>
          </inertia>
        </inertial>
        <collision name='third_link_collision'>
          <pose frame=''>0 0 0 0 -0 0</pose>
          <geometry>
            <cylinder>
              <length>0.6</length>
              <radius>0.05</radius>
            </cylinder>
          </geometry>
          <max_contacts>10</max_contacts>
          <surface>
            <contact>
              <ode/>
            </contact>
            <bounce/>
            <friction>
              <torsional>
                <ode/>
              </torsional>
              <ode/>
            </friction>
          </surface>
        </collision>
        <collision name='third_link_fixed_joint_lump__wrist_link_collision_1'>
          <pose frame=''>0 0 -0.45 0 -0 0</pose>
          <geometry>
            <box>
              <size>0.01 0.05 0.1</size>
            </box>
          </geometry>
          <max_contacts>10</max_contacts>
          <surface>
            <contact>
              <ode/>
            </contact>
            <bounce/>
            <friction>
              <torsional>
                <ode/>
              </torsional>
              <ode/>
            </friction>
          </surface>
        </collision>
        <visual name='third_link_visual'>
          <pose frame=''>0 0 -0.15 0 -0 0</pose>
          <geometry>
            <cylinder>
              <length>0.6</length>
              <radius>0.05</radius>
            </cylinder>
          </geometry>
        </visual>
        <visual name='third_link_fixed_joint_lump__wrist_link_visual_1'>
          <pose frame=''>0.05 0 -0.4 0 -0 0</pose>
          <geometry>
            <box>
              <size>0.01 0.05 0.1</size>
            </box>
          </geometry>
        </visual>
        <self_collide>0</self_collide>
        <kinematic>0</kinematic>
        <gravity>1</gravity>
      </link>
      <joint name='second_joint_to_third_joint' type='prismatic'>
        <child>third_link</child>
        <parent>second_joint</parent>
        <axis>
          <xyz>0 0 1</xyz>
          <limit>
            <lower>-0.3</lower>
            <upper>0</upper>
            <effort>1000</effort>
            <velocity>0.5</velocity>
          </limit>
          <dynamics>
            <spring_reference>0</spring_reference>
            <spring_stiffness>0</spring_stiffness>
          </dynamics>
          <use_parent_model_frame>1</use_parent_model_frame>
        </axis>
      </joint>
      <pose frame=''>0 0 0 0 -0 0</pose>
    </model>
    <state world_name='default'>
      <sim_time>25 921000000</sim_time>
      <real_time>26 109327659</real_time>
      <wall_time>1537383893 140998915</wall_time>
      <iterations>25921</iterations>
      <model name='ground_plane'>
        <pose frame=''>0 0 0 0 -0 0</pose>
        <scale>1 1 1</scale>
        <link name='link'>
          <pose frame=''>0 0 0 0 -0 0</pose>
          <velocity>0 0 0 0 -0 0</velocity>
          <acceleration>0 0 0 0 -0 0</acceleration>
          <wrench>0 0 0 0 -0 0</wrench>
        </link>
      </model>
      <model name='scara'>
        <pose frame=''>0.335289 0.361414 0.258939 1.29258 -0.827037 2.51939</pose>
        <scale>1 1 1</scale>
        <link name='base_link'>
          <pose frame=''>0.335289 0.361414 0.258939 1.29258 -0.827037 2.51939</pose>
          <velocity>-0.008548 0.008032 -2.7e-05 -0.062263 -0.046257 -0.01349</velocity>
          <acceleration>-0.528077 -0.766362 10.0752 3.1389 0.29233 3.14159</acceleration>
          <wrench>-528.077 -766.362 10075.2 0 -0 0</wrench>
        </link>
        <link name='first_joint'>
          <pose frame=''>0.369595 1.23573 1.03807 -0.857824 1.28228 -0.137206</pose>
          <velocity>-0.029176 0.01538 0.003629 -0.012809 -0.028458 -0.004017</velocity>
          <acceleration>-17.5339 31.231 8.93063 -3.14113 0.578808 -0.826362</acceleration>
          <wrench>-350.678 624.62 178.613 0 -0 0</wrench>
        </link>
        <link name='first_link'>
          <pose frame=''>0.878743 0.859093 0.39855 1.30321 -0.790244 2.50457</pose>
          <velocity>-0.00869 0.007137 0.0116 -0.016865 -0.022986 -0.001703</velocity>
          <acceleration>4.22534 -3.19753 22.7613 3.00886 -0.001586 0.534713</acceleration>
          <wrench>42.2534 -31.9753 227.613 0 -0 0</wrench>
        </link>
        <link name='second_joint'>
          <pose frame=''>0.623245 1.20069 0.175292 1.38052 0.18031 2.2777</pose>
          <velocity>-0.013411 0.011955 0.013239 -0.081892 -0.089471 -0.027289</velocity>
          <acceleration>5.00169 -4.75612 28.0566 -1.93942 1.3643 -1.29946</acceleration>
          <wrench>50.0169 -47.5612 280.566 0 -0 0</wrench>
        </link>
        <link name='third_link'>
          <pose frame=''>0.405857 1.00162 0.119465 1.3805 0.180312 2.2777</pose>
          <velocity>-0.009313 0.013415 0.010509 -0.085497 -0.093553 -0.025319</velocity>
          <acceleration>2.21142 0.111072 29.4811 -2.98159 0.476263 -0.804628</acceleration>
          <wrench>44.2285 2.22144 589.623 0 -0 0</wrench>
        </link>
      </model>

      <joint name="fixed to ground" type="revolute">
        <parent>world</parent>
        <child>scara::base_link</child>
         <axis>
          <limit>
            <lower>0</lower>
            <upper>0</upper>
          </limit>
          <xyz>0 0 1</xyz>
          </axis>
      </joint>

      <light name='sun'>
        <pose frame=''>0 0 10 0 -0 0</pose>
      </light>
    </state>
    <gui fullscreen='0'>
      <camera name='user_camera'>
        <pose frame=''>4.97832 -5.02554 1.99036 0 0.275643 2.35619</pose>
        <view_controller>orbit</view_controller>
        <projection_type>perspective</projection_type>
      </camera>
    </gui>
  </world>
</sdf>
